<?xml version="1.0" encoding="utf-8"?>
<!-- =================================================================================== -->
<!-- |    This document was autogenerated by xacro from myArm.xacro                    | -->
<!-- |    EDITING THIS FILE BY HAND IS NOT RECOMMENDED                                 | -->
<!-- =================================================================================== -->
<!-- HEBI 6-DOF Robot arm kit -->
<robot name="CNU_HEBI_Arm">
  <!-- *************************** XACRO MACROS *************************** -->
  <!-- ************************* ROBOT DEFINITION ************************* -->
  <link name="world"/>
  <joint name="world_joint" type="fixed">
    <origin rpy="0 0 0" xyz="0 0 0"/>
    <parent link="world"/>
    <child link="base"/>
  </joint>
  <link name="base">
    <visual>
      <origin rpy="0 0 0" xyz="0 0 0.0675"/>
      <geometry>
        <box size="0.25 0.5 0.135"/>
      </geometry>
      <material name="silver">
        <color rgba="0.6 0.6 0.6 1"/>
      </material>
    </visual>
    <collision>
      <origin rpy="0 0 0" xyz="0 0 0.0675"/>
      <geometry>
        <box size="0.25 0.5 0.135"/>
      </geometry>
    </collision>
    <inertial>
      <origin rpy="0 0 0" xyz=".125 0 -.0254"/>
      <mass value="1.0"/>
      <inertia ixx="1.0" ixy="0.0" ixz="0.0" iyy="1.0" iyz="0.0" izz="1.0"/>
    </inertial>
  </link>
  <joint name="base_base" type="fixed">
    <parent link="base"/>
    <child link="HEBI/base/INPUT_INTERFACE"/>
    <origin rpy="0 0 0" xyz="0 0 0.135"/>
  </joint>
  <link name="HEBI/base/INPUT_INTERFACE">
    <visual>
      <origin rpy="0 0 0" xyz="0 0 0"/>
      <geometry>
        <mesh filename="package://hebiros_description/meshes/x5.stl" scale="0.001 0.001 0.001"/>
      </geometry>
      <material name="red">
        <color rgba=".82 0.06 0.06 1"/>
      </material>
    </visual>
    <collision>
      <origin rpy="0 0 0" xyz="0 0 0"/>
      <geometry>
        <mesh filename="package://hebiros_description/meshes/x5.stl" scale="0.001 0.001 0.001"/>
      </geometry>
    </collision>
    <inertial>
      <origin rpy="0 0 0" xyz="-0.0142 -0.0031 0.0165"/>
      <mass value="0.335"/>
      <inertia ixx="0.00015" ixy="0.0000341" ixz="0.0000118" iyy="0.000255" iyz="0.00000229" izz="0.000350"/>
    </inertial>
  </link>
  <joint name="HEBI/base/X5_4" type="continuous">
    <parent link="HEBI/base/INPUT_INTERFACE"/>
    <child link="shoulder_bracket/INPUT_INTERFACE"/>
    <origin rpy="0 0 0" xyz="0 0 0.031"/>
    <axis xyz="0 0 1"/>
    <limit effort="7.0" velocity="32"/>
    <dynamics damping="0.1" friction="0.1"/>
  </joint>
  <gazebo reference="HEBI/base/INPUT_INTERFACE">
    <selfCollide>true</selfCollide>
    <gravity>true</gravity>
    <sensor name="HEBI/base/imu_sensor" type="imu">
      <always_on>true</always_on>
      <update_rate>100</update_rate>
      <visualize>true</visualize>
      <plugin filename="libgazebo_ros_imu_sensor.so" name="imu_plugin">
        <topicName>/hebiros_gazebo_plugin/imu/HEBI/base</topicName>
        <bodyName>HEBI/base/imu_link</bodyName>
        <updateRateHZ>10.0</updateRateHZ>
        <gaussianNoise>0.0</gaussianNoise>
        <xyzOffset>0.025 0 0.003</xyzOffset>
        <rpyOffset>0 0 0</rpyOffset>
        <frameName>HEBI/base/imu_link</frameName>
      </plugin>
      <pose>0 0 0 0 0 0</pose>
    </sensor>
  </gazebo>
  <link name="shoulder_bracket/INPUT_INTERFACE">
    <visual>
      <origin rpy="1.57079632679 0 1.57079632679" xyz="0 0 0.005"/>
      <geometry>
        <mesh filename="package://hebiros_description/meshes/PM-2149-01.stl" scale="0.001 0.001 0.001"/>
      </geometry>
      <material name="black">
        <color rgba="0 0 0 1"/>
      </material>
    </visual>
    <visual>
      <origin rpy="1.57079632679 0 0" xyz="0 -.03 .04"/>
      <geometry>
        <mesh filename="package://hebiros_description/meshes/PM-2150-01R.stl" scale="0.001 0.001 0.001"/>
      </geometry>
      <material name="black">
        <color rgba="0 0 0 1"/>
      </material>
    </visual>
    <collision>
      <origin rpy="1.57079632679 0 1.57079632679" xyz="0 0 0.005"/>
      <geometry>
        <mesh filename="package://hebiros_description/meshes/PM-2149-01.stl" scale="0.001 0.001 0.001"/>
      </geometry>
    </collision>
    <collision>
      <origin rpy="1.57079632679 0 0" xyz="0 -.03 .04"/>
      <geometry>
        <mesh filename="package://hebiros_description/meshes/PM-2150-01R.stl" scale="0.001 0.001 0.001"/>
      </geometry>
    </collision>
    <!-- NOTE: inertia is just modelled as small sphere, and could be improved. -->
    <inertial>
      <origin rpy="0 0 0" xyz="0 -0.01875 .0275"/>
      <mass value="0.215"/>
      <inertia ixx="0.0003096" ixy="0.0" ixz="0.0" iyy="0.0003096" iyz="0.0" izz="0.0003096"/>
    </inertial>
  </link>
  <joint name="shoulder_bracket/OUTPUT_INTERFACE" type="fixed">
    <parent link="shoulder_bracket/INPUT_INTERFACE"/>
    <child link="HEBI/shoulder/INPUT_INTERFACE"/>
    <origin rpy="1.57079632679 0 0" xyz="0 -.0375 .055"/>
  </joint>
  <gazebo reference="shoulder_bracket/INPUT_INTERFACE">
    <selfCollide>true</selfCollide>
  </gazebo>
  <link name="HEBI/shoulder/INPUT_INTERFACE">
    <visual>
      <origin rpy="0 0 0" xyz="0 0 0"/>
      <geometry>
        <mesh filename="package://hebiros_description/meshes/x5.stl" scale="0.001 0.001 0.001"/>
      </geometry>
      <material name="red">
        <color rgba=".82 0.06 0.06 1"/>
      </material>
    </visual>
    <collision>
      <origin rpy="0 0 0" xyz="0 0 0"/>
      <geometry>
        <mesh filename="package://hebiros_description/meshes/x5.stl" scale="0.001 0.001 0.001"/>
      </geometry>
    </collision>
    <inertial>
      <origin rpy="0 0 0" xyz="-0.0142 -0.0031 0.0165"/>
      <mass value="0.360"/>
      <inertia ixx="0.00015" ixy="0.0000341" ixz="0.0000118" iyy="0.000255" iyz="0.00000229" izz="0.000350"/>
    </inertial>
  </link>
  <joint name="HEBI/shoulder/X5_9" type="continuous">
    <parent link="HEBI/shoulder/INPUT_INTERFACE"/>
    <child link="shoulder_elbow/INPUT_INTERFACE"/>
    <origin rpy="0 0 0" xyz="0 0 0.031"/>
    <axis xyz="0 0 1"/>
    <limit effort="13.0" velocity="14"/>
    <dynamics damping="0.1" friction="0.1"/>
  </joint>
  <gazebo reference="HEBI/shoulder/INPUT_INTERFACE">
    <selfCollide>true</selfCollide>
    <gravity>true</gravity>
    <sensor name="HEBI/shoulder/imu_sensor" type="imu">
      <always_on>true</always_on>
      <update_rate>100</update_rate>
      <visualize>true</visualize>
      <plugin filename="libgazebo_ros_imu_sensor.so" name="imu_plugin">
        <topicName>/hebiros_gazebo_plugin/imu/HEBI/shoulder</topicName>
        <bodyName>HEBI/shoulder/imu_link</bodyName>
        <updateRateHZ>10.0</updateRateHZ>
        <gaussianNoise>0.0</gaussianNoise>
        <xyzOffset>0.025 0 0.003</xyzOffset>
        <rpyOffset>0 0 0</rpyOffset>
        <frameName>HEBI/shoulder/imu_link</frameName>
      </plugin>
      <pose>0 0 0 0 0 0</pose>
    </sensor>
  </gazebo>
  <link name="shoulder_elbow/INPUT_INTERFACE">
    <visual>
      <origin rpy="0 0 0" xyz="0 0 0"/>
      <geometry>
        <mesh filename="package://hebiros_description/meshes/A-2038-02.stl"/>
      </geometry>
      <material name="black">
        <color rgba="0 0 0 1"/>
      </material>
    </visual>
    <visual>
      <origin rpy="0 1.57075 0" xyz="0.1625 0 0.02"/>
      <geometry>
        <cylinder length="0.2996" radius=".016"/>
      </geometry>
      <material name="silver">
        <color rgba="0.6 0.6 0.6 1"/>
      </material>
    </visual>
    <visual>
      <origin rpy="-1.57079632679 0 0" xyz="0.325 -0.02 0.02"/>
      <geometry>
        <mesh filename="package://hebiros_description/meshes/A-2039-02.stl"/>
      </geometry>
      <material name="black">
        <color rgba="0 0 0 1"/>
      </material>
    </visual>
    <collision>
      <origin rpy="0 0 0" xyz="0 0 0"/>
      <geometry>
        <mesh filename="package://hebiros_description/meshes/A-2038-02.stl"/>
      </geometry>
    </collision>
    <collision>
      <origin rpy="0 1.57075 0" xyz="0.1625 0 0.02"/>
      <geometry>
        <cylinder length="0.2996" radius=".016"/>
      </geometry>
    </collision>
    <collision>
      <origin rpy="-1.57079632679 0 0" xyz="0.325 -0.02 0.02"/>
      <geometry>
        <mesh filename="package://hebiros_description/meshes/A-2039-02.stl"/>
      </geometry>
    </collision>
    <!-- Approximate inertia as thin rod about x axis -->
    <inertial>
      <origin rpy="0 0 0" xyz="0.1625 0 0.02"/>
      <mass value="0.402"/>
      <inertia ixx="0.0" ixy="0.0" ixz="0.0" iyy="0.0035384375" iyz="0.0" izz="0.0035384375"/>
    </inertial>
  </link>
  <joint name="shoulder_elbow/OUTPUT_JOINT" type="fixed">
    <parent link="shoulder_elbow/INPUT_INTERFACE"/>
    <child link="HEBI/elbow/INPUT_INTERFACE"/>
    <origin rpy="1.57079632679 0 0" xyz="0.325 -0.02 0.02"/>
  </joint>
  <gazebo reference="shoulder_elbow/INPUT_INTERFACE">
    <selfCollide>true</selfCollide>
  </gazebo>
  <link name="HEBI/elbow/INPUT_INTERFACE">
    <visual>
      <origin rpy="0 0 0" xyz="0 0 0"/>
      <geometry>
        <mesh filename="package://hebiros_description/meshes/x5.stl" scale="0.001 0.001 0.001"/>
      </geometry>
      <material name="red">
        <color rgba=".82 0.06 0.06 1"/>
      </material>
    </visual>
    <collision>
      <origin rpy="0 0 0" xyz="0 0 0"/>
      <geometry>
        <mesh filename="package://hebiros_description/meshes/x5.stl" scale="0.001 0.001 0.001"/>
      </geometry>
    </collision>
    <inertial>
      <origin rpy="0 0 0" xyz="-0.0142 -0.0031 0.0165"/>
      <mass value="0.335"/>
      <inertia ixx="0.00015" ixy="0.0000341" ixz="0.0000118" iyy="0.000255" iyz="0.00000229" izz="0.000350"/>
    </inertial>
  </link>
  <joint name="HEBI/elbow/X5_4" type="continuous">
    <parent link="HEBI/elbow/INPUT_INTERFACE"/>
    <child link="elbow_wrist1/INPUT_INTERFACE"/>
    <origin rpy="0 0 0" xyz="0 0 0.031"/>
    <axis xyz="0 0 1"/>
    <limit effort="7.0" velocity="32"/>
    <dynamics damping="0.1" friction="0.1"/>
  </joint>
  <gazebo reference="HEBI/elbow/INPUT_INTERFACE">
    <selfCollide>true</selfCollide>
    <gravity>true</gravity>
    <sensor name="HEBI/elbow/imu_sensor" type="imu">
      <always_on>true</always_on>
      <update_rate>100</update_rate>
      <visualize>true</visualize>
      <plugin filename="libgazebo_ros_imu_sensor.so" name="imu_plugin">
        <topicName>/hebiros_gazebo_plugin/imu/HEBI/elbow</topicName>
        <bodyName>HEBI/elbow/imu_link</bodyName>
        <updateRateHZ>10.0</updateRateHZ>
        <gaussianNoise>0.0</gaussianNoise>
        <xyzOffset>0.025 0 0.003</xyzOffset>
        <rpyOffset>0 0 0</rpyOffset>
        <frameName>HEBI/elbow/imu_link</frameName>
      </plugin>
      <pose>0 0 0 0 0 0</pose>
    </sensor>
  </gazebo>
  <link name="elbow_wrist1/INPUT_INTERFACE">
    <visual>
      <origin rpy="0 0 0" xyz="0 0 0"/>
      <geometry>
        <mesh filename="package://hebiros_description/meshes/A-2038-02.stl"/>
      </geometry>
      <material name="black">
        <color rgba="0 0 0 1"/>
      </material>
    </visual>
    <visual>
      <origin rpy="0 1.57075 0" xyz="0.1625 0 0.02"/>
      <geometry>
        <cylinder length="0.2996" radius=".016"/>
      </geometry>
      <material name="silver">
        <color rgba="0.6 0.6 0.6 1"/>
      </material>
    </visual>
    <visual>
      <origin rpy="0 0 0" xyz="0.325 0.0 0.04"/>
      <geometry>
        <mesh filename="package://hebiros_description/meshes/A-2039-02.stl"/>
      </geometry>
      <material name="black">
        <color rgba="0 0 0 1"/>
      </material>
    </visual>
    <collision>
      <origin rpy="0 0 0" xyz="0 0 0"/>
      <geometry>
        <mesh filename="package://hebiros_description/meshes/A-2038-02.stl"/>
      </geometry>
    </collision>
    <collision>
      <origin rpy="0 1.57075 0" xyz="0.1625 0 0.02"/>
      <geometry>
        <cylinder length="0.2996" radius=".016"/>
      </geometry>
    </collision>
    <collision>
      <origin rpy="0 0 0" xyz="0.325 0.0 0.04"/>
      <geometry>
        <mesh filename="package://hebiros_description/meshes/A-2039-02.stl"/>
      </geometry>
    </collision>
    <!-- Approximate inertia as thin rod about x axis -->
    <inertial>
      <origin rpy="0 0 0" xyz="0.1625 0 0.02"/>
      <mass value="0.402"/>
      <inertia ixx="0.0" ixy="0.0" ixz="0.0" iyy="0.0035384375" iyz="0.0" izz="0.0035384375"/>
    </inertial>
  </link>
  <joint name="elbow_wrist1/OUTPUT_JOINT" type="fixed">
    <parent link="elbow_wrist1/INPUT_INTERFACE"/>
    <child link="HEBI/wrist/INPUT_INTERFACE"/>
    <origin rpy="0 0 0" xyz="0.325 -0.0 0.04"/>
  </joint>
  <gazebo reference="elbow_wrist1/INPUT_INTERFACE">
    <selfCollide>true</selfCollide>
  </gazebo>
  <link name="HEBI/wrist/INPUT_INTERFACE">
    <visual>
      <origin rpy="0 0 0" xyz="0 0 0"/>
      <geometry>
        <mesh filename="package://hebiros_description/meshes/x5.stl" scale="0.001 0.001 0.001"/>
      </geometry>
      <material name="red">
        <color rgba=".82 0.06 0.06 1"/>
      </material>
    </visual>
    <collision>
      <origin rpy="0 0 0" xyz="0 0 0"/>
      <geometry>
        <mesh filename="package://hebiros_description/meshes/x5.stl" scale="0.001 0.001 0.001"/>
      </geometry>
    </collision>
    <inertial>
      <origin rpy="0 0 0" xyz="-0.0142 -0.0031 0.0165"/>
      <mass value="0.360"/>
      <inertia ixx="0.00015" ixy="0.0000341" ixz="0.0000118" iyy="0.000255" iyz="0.00000229" izz="0.000350"/>
    </inertial>
  </link>
  <joint name="HEBI/wrist/X5_9" type="continuous">
    <parent link="HEBI/wrist/INPUT_INTERFACE"/>
    <child link="wrist_paddle/INPUT_INTERFACE"/>
    <origin rpy="0 0 0" xyz="0 0 0.031"/>
    <axis xyz="0 0 1"/>
    <limit effort="13.0" velocity="14"/>
    <dynamics damping="0.1" friction="0.1"/>
  </joint>
  <gazebo reference="HEBI/wrist/INPUT_INTERFACE">
    <selfCollide>true</selfCollide>
    <gravity>true</gravity>
    <sensor name="HEBI/wrist/imu_sensor" type="imu">
      <always_on>true</always_on>
      <update_rate>100</update_rate>
      <visualize>true</visualize>
      <plugin filename="libgazebo_ros_imu_sensor.so" name="imu_plugin">
        <topicName>/hebiros_gazebo_plugin/imu/HEBI/wrist</topicName>
        <bodyName>HEBI/wrist/imu_link</bodyName>
        <updateRateHZ>10.0</updateRateHZ>
        <gaussianNoise>0.0</gaussianNoise>
        <xyzOffset>0.025 0 0.003</xyzOffset>
        <rpyOffset>0 0 0</rpyOffset>
        <frameName>HEBI/wrist/imu_link</frameName>
      </plugin>
      <pose>0 0 0 0 0 0</pose>
    </sensor>
  </gazebo>
  <link name="wrist_paddle/INPUT_INTERFACE">
    <visual>
      <origin rpy="0 0 0" xyz="0 0 0.0375"/>
      <geometry>
        <cylinder length="0.075" radius=".016"/>
      </geometry>
      <material name="orange">
        <color rgba="1.0 0.423529411765 0.0392156862745 1.0"/>
      </material>
    </visual>
    <visual>
      <origin rpy="0 0 0" xyz="0 0 0.0875"/>
      <geometry>
        <cylinder length="0.025" radius="0.0508"/>
      </geometry>
      <material name="orange">
        <color rgba="1.0 0.423529411765 0.0392156862745 1.0"/>
      </material>
    </visual>
    <collision>
      <origin rpy="0 0 0" xyz="0 0 0.0375"/>
      <geometry>
        <cylinder length="0.075" radius=".016"/>
      </geometry>
    </collision>
    <collision>
      <origin rpy="0 0 0" xyz="0 0 0.0875"/>
      <geometry>
        <cylinder length="0.025" radius="0.0508"/>
      </geometry>
    </collision>
    <!-- Approximate inertia as thin rod about x axis -->
    <inertial>
      <origin rpy="0 0 0" xyz="0 0 0.0375"/>
      <mass value="0.312"/>
      <inertia ixx="0.0" ixy="0.0" ixz="0.0" iyy="0.00026" iyz="0.0" izz="0.00026"/>
    </inertial>
    <inertial>
      <origin rpy="0 0 0" xyz="0 0 0.0875"/>
      <mass value="0.04"/>
      <inertia ixx="0.0" ixy="0.0" ixz="0.0" iyy="2.08333333333e-06" iyz="0.0" izz="2.08333333333e-06"/>
    </inertial>
  </link>
  <joint name="wrist_paddle/OUTPUT_JOINT" type="fixed">
    <parent link="wrist_paddle/INPUT_INTERFACE"/>
    <child link="end_effector/INPUT_INTERFACE"/>
    <origin rpy="0 0 0" xyz="0 0 0.1"/>
  </joint>
  <gazebo reference="wrist_paddle/INPUT_INTERFACE">
    <selfCollide>true</selfCollide>
  </gazebo>
  <!-- end link -->
  <link name="end_effector/INPUT_INTERFACE">
  </link>
  <gazebo reference="base">
    <selfCollide>true</selfCollide>
  </gazebo>
  <gazebo>
    <plugin filename="libhebiros_gazebo_plugin.so" name="hebiros_gazebo_plugin">
    </plugin>
  </gazebo>
</robot>

